[2024-05-13T12:33:16.113+0000] {local_task_job_runner.py:120} INFO - ::group::Pre task execution logs
[2024-05-13T12:33:16.159+0000] {taskinstance.py:2073} INFO - Dependencies all met for dep_context=non-requeueable deps ti=<TaskInstance: ETL1.ParallelSensorTasks.FetchSensor_d1489cf0-facd-11ed-a890-0242bed38519 manual__2024-05-13T12:29:45.680336+00:00 [queued]>
[2024-05-13T12:33:16.180+0000] {taskinstance.py:2073} INFO - Dependencies all met for dep_context=requeueable deps ti=<TaskInstance: ETL1.ParallelSensorTasks.FetchSensor_d1489cf0-facd-11ed-a890-0242bed38519 manual__2024-05-13T12:29:45.680336+00:00 [queued]>
[2024-05-13T12:33:16.182+0000] {taskinstance.py:2303} INFO - Starting attempt 2 of 4
[2024-05-13T12:33:16.239+0000] {taskinstance.py:2327} INFO - Executing <Task(PythonOperator): ParallelSensorTasks.FetchSensor_d1489cf0-facd-11ed-a890-0242bed38519> on 2024-05-13 12:29:45.680336+00:00
[2024-05-13T12:33:16.283+0000] {warnings.py:110} WARNING - /home/***/.local/lib/python3.12/site-packages/***/task/task_runner/standard_task_runner.py:61: DeprecationWarning: This process (pid=398) is multi-threaded, use of fork() may lead to deadlocks in the child.
  pid = os.fork()

[2024-05-13T12:33:16.293+0000] {standard_task_runner.py:63} INFO - Started process 463 to run task
[2024-05-13T12:33:16.290+0000] {standard_task_runner.py:90} INFO - Running: ['***', 'tasks', 'run', 'ETL1', 'ParallelSensorTasks.FetchSensor_d1489cf0-facd-11ed-a890-0242bed38519', 'manual__2024-05-13T12:29:45.680336+00:00', '--job-id', '8', '--raw', '--subdir', 'DAGS_FOLDER/fetchDataFromMongo.py', '--cfg-path', '/tmp/tmp1ji9r5e9']
[2024-05-13T12:33:16.297+0000] {standard_task_runner.py:91} INFO - Job 8: Subtask ParallelSensorTasks.FetchSensor_d1489cf0-facd-11ed-a890-0242bed38519
[2024-05-13T12:33:17.275+0000] {task_command.py:426} INFO - Running <TaskInstance: ETL1.ParallelSensorTasks.FetchSensor_d1489cf0-facd-11ed-a890-0242bed38519 manual__2024-05-13T12:29:45.680336+00:00 [running]> on host 560e2c556382
[2024-05-13T12:33:17.497+0000] {taskinstance.py:2644} INFO - Exporting env vars: AIRFLOW_CTX_DAG_OWNER='Shubham Bhatt' AIRFLOW_CTX_DAG_ID='ETL1' AIRFLOW_CTX_TASK_ID='ParallelSensorTasks.FetchSensor_d1489cf0-facd-11ed-a890-0242bed38519' AIRFLOW_CTX_EXECUTION_DATE='2024-05-13T12:29:45.680336+00:00' AIRFLOW_CTX_TRY_NUMBER='2' AIRFLOW_CTX_DAG_RUN_ID='manual__2024-05-13T12:29:45.680336+00:00'
[2024-05-13T12:33:17.503+0000] {taskinstance.py:430} INFO - ::endgroup::
[2024-05-13T12:33:21.972+0000] {logging_mixin.py:188} INFO - E11000 duplicate key error collection: pvvnl.transformed_data index: _id_ dup key: { _id: "00b1b366-ef28-47a8-acd8-762e9e561cd7_2024-01-01 07:00:00" }, full error: {'index': 0, 'code': 11000, 'keyPattern': {'_id': 1}, 'keyValue': {'_id': '00b1b366-ef28-47a8-acd8-762e9e561cd7_2024-01-01 07:00:00'}, 'errmsg': 'E11000 duplicate key error collection: pvvnl.transformed_data index: _id_ dup key: { _id: "00b1b366-ef28-47a8-acd8-762e9e561cd7_2024-01-01 07:00:00" }'}
[2024-05-13T12:33:27.521+0000] {logging_mixin.py:188} INFO - E11000 duplicate key error collection: pvvnl.transformed_data index: _id_ dup key: { _id: "00800197-5ccf-4613-9602-c7a7ac7297b9_2024-03-29 14:45:00" }, full error: {'index': 0, 'code': 11000, 'keyPattern': {'_id': 1}, 'keyValue': {'_id': '00800197-5ccf-4613-9602-c7a7ac7297b9_2024-03-29 14:45:00'}, 'errmsg': 'E11000 duplicate key error collection: pvvnl.transformed_data index: _id_ dup key: { _id: "00800197-5ccf-4613-9602-c7a7ac7297b9_2024-03-29 14:45:00" }'}
[2024-05-13T12:33:29.705+0000] {logging_mixin.py:188} INFO - E11000 duplicate key error collection: pvvnl.transformed_data index: _id_ dup key: { _id: "015856ea-1f27-4d63-9497-07fd9b907ddf_2024-03-29 13:00:00" }, full error: {'index': 0, 'code': 11000, 'keyPattern': {'_id': 1}, 'keyValue': {'_id': '015856ea-1f27-4d63-9497-07fd9b907ddf_2024-03-29 13:00:00'}, 'errmsg': 'E11000 duplicate key error collection: pvvnl.transformed_data index: _id_ dup key: { _id: "015856ea-1f27-4d63-9497-07fd9b907ddf_2024-03-29 13:00:00" }'}
[2024-05-13T12:33:35.922+0000] {logging_mixin.py:188} INFO - E11000 duplicate key error collection: pvvnl.transformed_data index: _id_ dup key: { _id: "012dbb89-8dc5-482c-901a-16837a18dc0b_2024-02-23 19:15:00" }, full error: {'index': 0, 'code': 11000, 'keyPattern': {'_id': 1}, 'keyValue': {'_id': '012dbb89-8dc5-482c-901a-16837a18dc0b_2024-02-23 19:15:00'}, 'errmsg': 'E11000 duplicate key error collection: pvvnl.transformed_data index: _id_ dup key: { _id: "012dbb89-8dc5-482c-901a-16837a18dc0b_2024-02-23 19:15:00" }'}
[2024-05-13T12:34:09.431+0000] {logging_mixin.py:188} INFO - 13.127.57.185:27017: timed out (configured timeouts: socketTimeoutMS: 20000.0ms, connectTimeoutMS: 20000.0ms), Timeout: 30s, Topology Description: <TopologyDescription id: 664208a12c12ef693ebcf7d4, topology_type: Unknown, servers: [<ServerDescription ('13.127.57.185', 27017) server_type: Unknown, rtt: None, error=NetworkTimeout('13.127.57.185:27017: timed out (configured timeouts: socketTimeoutMS: 20000.0ms, connectTimeoutMS: 20000.0ms)')>]>
[2024-05-13T12:34:10.223+0000] {logging_mixin.py:188} INFO - Error: 13.127.57.185:27017: timed out (configured timeouts: socketTimeoutMS: 20000.0ms, connectTimeoutMS: 20000.0ms), Timeout: 30s, Topology Description: <TopologyDescription id: 664208a22c12ef693ebcf7d5, topology_type: Unknown, servers: [<ServerDescription ('13.127.57.185', 27017) server_type: Unknown, rtt: None, error=NetworkTimeout('13.127.57.185:27017: timed out (configured timeouts: socketTimeoutMS: 20000.0ms, connectTimeoutMS: 20000.0ms)')>]>
[2024-05-13T12:34:12.799+0000] {logging_mixin.py:188} INFO - 'NoneType' object has no attribute 'empty'
[2024-05-13T12:34:17.664+0000] {job.py:218} ERROR - Job heartbeat got an exception
Traceback (most recent call last):
  File "/home/airflow/.local/lib/python3.12/site-packages/sqlalchemy/engine/base.py", line 3371, in _wrap_pool_connect
    return fn()
           ^^^^
  File "/home/airflow/.local/lib/python3.12/site-packages/sqlalchemy/pool/base.py", line 327, in connect
    return _ConnectionFairy._checkout(self)
           ^^^^^^^^^^^^^^^^^^^^^^^^^^^^^^^^
  File "/home/airflow/.local/lib/python3.12/site-packages/sqlalchemy/pool/base.py", line 894, in _checkout
    fairy = _ConnectionRecord.checkout(pool)
            ^^^^^^^^^^^^^^^^^^^^^^^^^^^^^^^^
  File "/home/airflow/.local/lib/python3.12/site-packages/sqlalchemy/pool/base.py", line 493, in checkout
    rec = pool._do_get()
          ^^^^^^^^^^^^^^
  File "/home/airflow/.local/lib/python3.12/site-packages/sqlalchemy/pool/impl.py", line 256, in _do_get
    return self._create_connection()
           ^^^^^^^^^^^^^^^^^^^^^^^^^
  File "/home/airflow/.local/lib/python3.12/site-packages/sqlalchemy/pool/base.py", line 273, in _create_connection
    return _ConnectionRecord(self)
           ^^^^^^^^^^^^^^^^^^^^^^^
  File "/home/airflow/.local/lib/python3.12/site-packages/sqlalchemy/pool/base.py", line 388, in __init__
    self.__connect()
  File "/home/airflow/.local/lib/python3.12/site-packages/sqlalchemy/pool/base.py", line 690, in __connect
    with util.safe_reraise():
  File "/home/airflow/.local/lib/python3.12/site-packages/sqlalchemy/util/langhelpers.py", line 70, in __exit__
    compat.raise_(
  File "/home/airflow/.local/lib/python3.12/site-packages/sqlalchemy/util/compat.py", line 211, in raise_
    raise exception
  File "/home/airflow/.local/lib/python3.12/site-packages/sqlalchemy/pool/base.py", line 686, in __connect
    self.dbapi_connection = connection = pool._invoke_creator(self)
                                         ^^^^^^^^^^^^^^^^^^^^^^^^^^
  File "/home/airflow/.local/lib/python3.12/site-packages/sqlalchemy/engine/create.py", line 574, in connect
    return dialect.connect(*cargs, **cparams)
           ^^^^^^^^^^^^^^^^^^^^^^^^^^^^^^^^^^
  File "/home/airflow/.local/lib/python3.12/site-packages/sqlalchemy/engine/default.py", line 598, in connect
    return self.dbapi.connect(*cargs, **cparams)
           ^^^^^^^^^^^^^^^^^^^^^^^^^^^^^^^^^^^^^
  File "/home/airflow/.local/lib/python3.12/site-packages/psycopg2/__init__.py", line 122, in connect
    conn = _connect(dsn, connection_factory=connection_factory, **kwasync)
           ^^^^^^^^^^^^^^^^^^^^^^^^^^^^^^^^^^^^^^^^^^^^^^^^^^^^^^^^^^^^^^^
psycopg2.OperationalError: could not translate host name "postgres" to address: Temporary failure in name resolution


The above exception was the direct cause of the following exception:

Traceback (most recent call last):
  File "/home/airflow/.local/lib/python3.12/site-packages/airflow/jobs/job.py", line 192, in heartbeat
    self._merge_from(Job._fetch_from_db(self, session))
                     ^^^^^^^^^^^^^^^^^^^^^^^^^^^^^^^^^
  File "/home/airflow/.local/lib/python3.12/site-packages/airflow/api_internal/internal_api_call.py", line 115, in wrapper
    return func(*args, **kwargs)
           ^^^^^^^^^^^^^^^^^^^^^
  File "/home/airflow/.local/lib/python3.12/site-packages/airflow/utils/session.py", line 76, in wrapper
    return func(*args, **kwargs)
           ^^^^^^^^^^^^^^^^^^^^^
  File "/home/airflow/.local/lib/python3.12/site-packages/airflow/utils/retries.py", line 89, in wrapped_function
    for attempt in run_with_db_retries(max_retries=retries, logger=logger, **retry_kwargs):
  File "/home/airflow/.local/lib/python3.12/site-packages/tenacity/__init__.py", line 347, in __iter__
    do = self.iter(retry_state=retry_state)
         ^^^^^^^^^^^^^^^^^^^^^^^^^^^^^^^^^^
  File "/home/airflow/.local/lib/python3.12/site-packages/tenacity/__init__.py", line 325, in iter
    raise retry_exc.reraise()
          ^^^^^^^^^^^^^^^^^^^
  File "/home/airflow/.local/lib/python3.12/site-packages/tenacity/__init__.py", line 158, in reraise
    raise self.last_attempt.result()
          ^^^^^^^^^^^^^^^^^^^^^^^^^^
  File "/usr/local/lib/python3.12/concurrent/futures/_base.py", line 449, in result
    return self.__get_result()
           ^^^^^^^^^^^^^^^^^^^
  File "/usr/local/lib/python3.12/concurrent/futures/_base.py", line 401, in __get_result
    raise self._exception
  File "/home/airflow/.local/lib/python3.12/site-packages/airflow/utils/retries.py", line 98, in wrapped_function
    return func(*args, **kwargs)
           ^^^^^^^^^^^^^^^^^^^^^
  File "/home/airflow/.local/lib/python3.12/site-packages/airflow/jobs/job.py", line 316, in _fetch_from_db
    session.merge(job)
  File "/home/airflow/.local/lib/python3.12/site-packages/sqlalchemy/orm/session.py", line 3056, in merge
    return self._merge(
           ^^^^^^^^^^^^
  File "/home/airflow/.local/lib/python3.12/site-packages/sqlalchemy/orm/session.py", line 3136, in _merge
    merged = self.get(
             ^^^^^^^^^
  File "/home/airflow/.local/lib/python3.12/site-packages/sqlalchemy/orm/session.py", line 2853, in get
    return self._get_impl(
           ^^^^^^^^^^^^^^^
  File "/home/airflow/.local/lib/python3.12/site-packages/sqlalchemy/orm/session.py", line 2975, in _get_impl
    return db_load_fn(
           ^^^^^^^^^^^
  File "/home/airflow/.local/lib/python3.12/site-packages/sqlalchemy/orm/loading.py", line 530, in load_on_pk_identity
    session.execute(
  File "/home/airflow/.local/lib/python3.12/site-packages/sqlalchemy/orm/session.py", line 1716, in execute
    conn = self._connection_for_bind(bind)
           ^^^^^^^^^^^^^^^^^^^^^^^^^^^^^^^
  File "/home/airflow/.local/lib/python3.12/site-packages/sqlalchemy/orm/session.py", line 1555, in _connection_for_bind
    return self._transaction._connection_for_bind(
           ^^^^^^^^^^^^^^^^^^^^^^^^^^^^^^^^^^^^^^^
  File "/home/airflow/.local/lib/python3.12/site-packages/sqlalchemy/orm/session.py", line 750, in _connection_for_bind
    conn = bind.connect()
           ^^^^^^^^^^^^^^
  File "/home/airflow/.local/lib/python3.12/site-packages/sqlalchemy/future/engine.py", line 412, in connect
    return super(Engine, self).connect()
           ^^^^^^^^^^^^^^^^^^^^^^^^^^^^^
  File "/home/airflow/.local/lib/python3.12/site-packages/sqlalchemy/engine/base.py", line 3325, in connect
    return self._connection_cls(self, close_with_result=close_with_result)
           ^^^^^^^^^^^^^^^^^^^^^^^^^^^^^^^^^^^^^^^^^^^^^^^^^^^^^^^^^^^^^^^
  File "/home/airflow/.local/lib/python3.12/site-packages/sqlalchemy/engine/base.py", line 96, in __init__
    else engine.raw_connection()
         ^^^^^^^^^^^^^^^^^^^^^^^
  File "/home/airflow/.local/lib/python3.12/site-packages/sqlalchemy/engine/base.py", line 3404, in raw_connection
    return self._wrap_pool_connect(self.pool.connect, _connection)
           ^^^^^^^^^^^^^^^^^^^^^^^^^^^^^^^^^^^^^^^^^^^^^^^^^^^^^^^
  File "/home/airflow/.local/lib/python3.12/site-packages/sqlalchemy/engine/base.py", line 3374, in _wrap_pool_connect
    Connection._handle_dbapi_exception_noconnection(
  File "/home/airflow/.local/lib/python3.12/site-packages/sqlalchemy/engine/base.py", line 2208, in _handle_dbapi_exception_noconnection
    util.raise_(
  File "/home/airflow/.local/lib/python3.12/site-packages/sqlalchemy/util/compat.py", line 211, in raise_
    raise exception
  File "/home/airflow/.local/lib/python3.12/site-packages/sqlalchemy/engine/base.py", line 3371, in _wrap_pool_connect
    return fn()
           ^^^^
  File "/home/airflow/.local/lib/python3.12/site-packages/sqlalchemy/pool/base.py", line 327, in connect
    return _ConnectionFairy._checkout(self)
           ^^^^^^^^^^^^^^^^^^^^^^^^^^^^^^^^
  File "/home/airflow/.local/lib/python3.12/site-packages/sqlalchemy/pool/base.py", line 894, in _checkout
    fairy = _ConnectionRecord.checkout(pool)
            ^^^^^^^^^^^^^^^^^^^^^^^^^^^^^^^^
  File "/home/airflow/.local/lib/python3.12/site-packages/sqlalchemy/pool/base.py", line 493, in checkout
    rec = pool._do_get()
          ^^^^^^^^^^^^^^
  File "/home/airflow/.local/lib/python3.12/site-packages/sqlalchemy/pool/impl.py", line 256, in _do_get
    return self._create_connection()
           ^^^^^^^^^^^^^^^^^^^^^^^^^
  File "/home/airflow/.local/lib/python3.12/site-packages/sqlalchemy/pool/base.py", line 273, in _create_connection
    return _ConnectionRecord(self)
           ^^^^^^^^^^^^^^^^^^^^^^^
  File "/home/airflow/.local/lib/python3.12/site-packages/sqlalchemy/pool/base.py", line 388, in __init__
    self.__connect()
  File "/home/airflow/.local/lib/python3.12/site-packages/sqlalchemy/pool/base.py", line 690, in __connect
    with util.safe_reraise():
  File "/home/airflow/.local/lib/python3.12/site-packages/sqlalchemy/util/langhelpers.py", line 70, in __exit__
    compat.raise_(
  File "/home/airflow/.local/lib/python3.12/site-packages/sqlalchemy/util/compat.py", line 211, in raise_
    raise exception
  File "/home/airflow/.local/lib/python3.12/site-packages/sqlalchemy/pool/base.py", line 686, in __connect
    self.dbapi_connection = connection = pool._invoke_creator(self)
                                         ^^^^^^^^^^^^^^^^^^^^^^^^^^
  File "/home/airflow/.local/lib/python3.12/site-packages/sqlalchemy/engine/create.py", line 574, in connect
    return dialect.connect(*cargs, **cparams)
           ^^^^^^^^^^^^^^^^^^^^^^^^^^^^^^^^^^
  File "/home/airflow/.local/lib/python3.12/site-packages/sqlalchemy/engine/default.py", line 598, in connect
    return self.dbapi.connect(*cargs, **cparams)
           ^^^^^^^^^^^^^^^^^^^^^^^^^^^^^^^^^^^^^
  File "/home/airflow/.local/lib/python3.12/site-packages/psycopg2/__init__.py", line 122, in connect
    conn = _connect(dsn, connection_factory=connection_factory, **kwasync)
           ^^^^^^^^^^^^^^^^^^^^^^^^^^^^^^^^^^^^^^^^^^^^^^^^^^^^^^^^^^^^^^^
sqlalchemy.exc.OperationalError: (psycopg2.OperationalError) could not translate host name "postgres" to address: Temporary failure in name resolution

(Background on this error at: https://sqlalche.me/e/14/e3q8)
[2024-05-13T12:34:17.724+0000] {job.py:226} ERROR - Job heartbeat failed with error. Scheduler is in unhealthy state
[2024-05-13T12:34:32.709+0000] {logging_mixin.py:188} INFO - E11000 duplicate key error collection: pvvnl.transformed_data index: _id_ dup key: { _id: "009f87e4-a013-4baf-baf0-e11be8b12db7_2024-01-01 01:15:00" }, full error: {'index': 0, 'code': 11000, 'keyPattern': {'_id': 1}, 'keyValue': {'_id': '009f87e4-a013-4baf-baf0-e11be8b12db7_2024-01-01 01:15:00'}, 'errmsg': 'E11000 duplicate key error collection: pvvnl.transformed_data index: _id_ dup key: { _id: "009f87e4-a013-4baf-baf0-e11be8b12db7_2024-01-01 01:15:00" }'}
[2024-05-13T12:34:32.732+0000] {logging_mixin.py:188} INFO - E11000 duplicate key error collection: pvvnl.transformed_data index: _id_ dup key: { _id: "016a7003-6af1-43bb-a374-662ca22b1c12_2024-02-23 19:30:00" }, full error: {'index': 0, 'code': 11000, 'keyPattern': {'_id': 1}, 'keyValue': {'_id': '016a7003-6af1-43bb-a374-662ca22b1c12_2024-02-23 19:30:00'}, 'errmsg': 'E11000 duplicate key error collection: pvvnl.transformed_data index: _id_ dup key: { _id: "016a7003-6af1-43bb-a374-662ca22b1c12_2024-02-23 19:30:00" }'}
[2024-05-13T12:34:32.733+0000] {python.py:237} INFO - Done. Returned value was: success
[2024-05-13T12:34:32.735+0000] {taskinstance.py:441} INFO - ::group::Post task execution logs
[2024-05-13T12:34:33.585+0000] {taskinstance.py:1205} INFO - Marking task as SUCCESS. dag_id=ETL1, task_id=ParallelSensorTasks.FetchSensor_d1489cf0-facd-11ed-a890-0242bed38519, execution_date=20240513T122945, start_date=20240513T123316, end_date=20240513T123433
[2024-05-13T12:34:33.793+0000] {local_task_job_runner.py:240} INFO - Task exited with return code 0
[2024-05-13T12:34:34.098+0000] {taskinstance.py:3482} INFO - 0 downstream tasks scheduled from follow-on schedule check
[2024-05-13T12:34:34.110+0000] {local_task_job_runner.py:222} INFO - ::endgroup::
